[2023-04-24T22:06:50.391+0200] {processor.py:153} INFO - Started process (PID=6718) to work on /Users/siddalingkattimani/airflow/dags/gpt_upload_csv_gcs.py
[2023-04-24T22:06:50.395+0200] {processor.py:743} INFO - Processing file /Users/siddalingkattimani/airflow/dags/gpt_upload_csv_gcs.py for tasks to queue
[2023-04-24T22:06:50.395+0200] {logging_mixin.py:137} INFO - [2023-04-24T22:06:50.395+0200] {dagbag.py:532} INFO - Filling up the DagBag from /Users/siddalingkattimani/airflow/dags/gpt_upload_csv_gcs.py
[2023-04-24T22:06:50.800+0200] {logging_mixin.py:137} INFO - [2023-04-24T22:06:50.794+0200] {dagbag.py:341} ERROR - Failed to import: /Users/siddalingkattimani/airflow/dags/gpt_upload_csv_gcs.py
Traceback (most recent call last):
  File "/Users/siddalingkattimani/dbt_env/lib/python3.11/site-packages/airflow/models/dagbag.py", line 337, in parse
    loader.exec_module(new_module)
  File "<frozen importlib._bootstrap_external>", line 940, in exec_module
  File "<frozen importlib._bootstrap>", line 241, in _call_with_frames_removed
  File "/Users/siddalingkattimani/airflow/dags/gpt_upload_csv_gcs.py", line 22, in <module>
    bucket_name = config.get("gcs", "bucket_name")
                  ^^^^^^^^^^^^^^^^^^^^^^^^^^^^^^^^
  File "/Library/Frameworks/Python.framework/Versions/3.11/lib/python3.11/configparser.py", line 797, in get
    d = self._unify_values(section, vars)
        ^^^^^^^^^^^^^^^^^^^^^^^^^^^^^^^^^
  File "/Library/Frameworks/Python.framework/Versions/3.11/lib/python3.11/configparser.py", line 1168, in _unify_values
    raise NoSectionError(section) from None
configparser.NoSectionError: No section: 'gcs'
[2023-04-24T22:06:50.801+0200] {processor.py:755} WARNING - No viable dags retrieved from /Users/siddalingkattimani/airflow/dags/gpt_upload_csv_gcs.py
[2023-04-24T22:06:51.657+0200] {processor.py:175} INFO - Processing /Users/siddalingkattimani/airflow/dags/gpt_upload_csv_gcs.py took 1.267 seconds
[2023-04-24T22:08:18.112+0200] {processor.py:153} INFO - Started process (PID=6750) to work on /Users/siddalingkattimani/airflow/dags/gpt_upload_csv_gcs.py
[2023-04-24T22:08:18.116+0200] {processor.py:743} INFO - Processing file /Users/siddalingkattimani/airflow/dags/gpt_upload_csv_gcs.py for tasks to queue
[2023-04-24T22:08:18.116+0200] {logging_mixin.py:137} INFO - [2023-04-24T22:08:18.116+0200] {dagbag.py:532} INFO - Filling up the DagBag from /Users/siddalingkattimani/airflow/dags/gpt_upload_csv_gcs.py
[2023-04-24T22:08:18.452+0200] {logging_mixin.py:137} INFO - [2023-04-24T22:08:18.451+0200] {dagbag.py:341} ERROR - Failed to import: /Users/siddalingkattimani/airflow/dags/gpt_upload_csv_gcs.py
Traceback (most recent call last):
  File "/Users/siddalingkattimani/dbt_env/lib/python3.11/site-packages/airflow/models/dagbag.py", line 337, in parse
    loader.exec_module(new_module)
  File "<frozen importlib._bootstrap_external>", line 940, in exec_module
  File "<frozen importlib._bootstrap>", line 241, in _call_with_frames_removed
  File "/Users/siddalingkattimani/airflow/dags/gpt_upload_csv_gcs.py", line 22, in <module>
    bucket_name = config.get("gcs", "bucket_name")
                  ^^^^^^^^^^^^^^^^^^^^^^^^^^^^^^^^
  File "/Library/Frameworks/Python.framework/Versions/3.11/lib/python3.11/configparser.py", line 797, in get
    d = self._unify_values(section, vars)
        ^^^^^^^^^^^^^^^^^^^^^^^^^^^^^^^^^
  File "/Library/Frameworks/Python.framework/Versions/3.11/lib/python3.11/configparser.py", line 1168, in _unify_values
    raise NoSectionError(section) from None
configparser.NoSectionError: No section: 'gcs'
[2023-04-24T22:08:18.453+0200] {processor.py:755} WARNING - No viable dags retrieved from /Users/siddalingkattimani/airflow/dags/gpt_upload_csv_gcs.py
[2023-04-24T22:08:18.932+0200] {processor.py:175} INFO - Processing /Users/siddalingkattimani/airflow/dags/gpt_upload_csv_gcs.py took 0.821 seconds
[2023-04-24T22:10:16.874+0200] {processor.py:153} INFO - Started process (PID=6867) to work on /Users/siddalingkattimani/airflow/dags/gpt_upload_csv_gcs.py
[2023-04-24T22:10:16.879+0200] {processor.py:743} INFO - Processing file /Users/siddalingkattimani/airflow/dags/gpt_upload_csv_gcs.py for tasks to queue
[2023-04-24T22:10:16.880+0200] {logging_mixin.py:137} INFO - [2023-04-24T22:10:16.880+0200] {dagbag.py:532} INFO - Filling up the DagBag from /Users/siddalingkattimani/airflow/dags/gpt_upload_csv_gcs.py
[2023-04-24T22:10:17.299+0200] {logging_mixin.py:137} INFO - [2023-04-24T22:10:17.293+0200] {dagbag.py:341} ERROR - Failed to import: /Users/siddalingkattimani/airflow/dags/gpt_upload_csv_gcs.py
Traceback (most recent call last):
  File "/Users/siddalingkattimani/dbt_env/lib/python3.11/site-packages/airflow/models/dagbag.py", line 337, in parse
    loader.exec_module(new_module)
  File "<frozen importlib._bootstrap_external>", line 940, in exec_module
  File "<frozen importlib._bootstrap>", line 241, in _call_with_frames_removed
  File "/Users/siddalingkattimani/airflow/dags/gpt_upload_csv_gcs.py", line 22, in <module>
    bucket_name = config.get("gcs", "bucket_name")
                  ^^^^^^^^^^^^^^^^^^^^^^^^^^^^^^^^
  File "/Library/Frameworks/Python.framework/Versions/3.11/lib/python3.11/configparser.py", line 797, in get
    d = self._unify_values(section, vars)
        ^^^^^^^^^^^^^^^^^^^^^^^^^^^^^^^^^
  File "/Library/Frameworks/Python.framework/Versions/3.11/lib/python3.11/configparser.py", line 1168, in _unify_values
    raise NoSectionError(section) from None
configparser.NoSectionError: No section: 'gcs'
[2023-04-24T22:10:17.300+0200] {processor.py:755} WARNING - No viable dags retrieved from /Users/siddalingkattimani/airflow/dags/gpt_upload_csv_gcs.py
[2023-04-24T22:10:17.764+0200] {processor.py:175} INFO - Processing /Users/siddalingkattimani/airflow/dags/gpt_upload_csv_gcs.py took 0.891 seconds
[2023-04-24T22:12:19.616+0200] {processor.py:153} INFO - Started process (PID=6981) to work on /Users/siddalingkattimani/airflow/dags/gpt_upload_csv_gcs.py
[2023-04-24T22:12:19.620+0200] {processor.py:743} INFO - Processing file /Users/siddalingkattimani/airflow/dags/gpt_upload_csv_gcs.py for tasks to queue
[2023-04-24T22:12:19.620+0200] {logging_mixin.py:137} INFO - [2023-04-24T22:12:19.620+0200] {dagbag.py:532} INFO - Filling up the DagBag from /Users/siddalingkattimani/airflow/dags/gpt_upload_csv_gcs.py
[2023-04-24T22:12:19.934+0200] {logging_mixin.py:137} INFO - [2023-04-24T22:12:19.933+0200] {dagbag.py:341} ERROR - Failed to import: /Users/siddalingkattimani/airflow/dags/gpt_upload_csv_gcs.py
Traceback (most recent call last):
  File "/Users/siddalingkattimani/dbt_env/lib/python3.11/site-packages/airflow/models/dagbag.py", line 337, in parse
    loader.exec_module(new_module)
  File "<frozen importlib._bootstrap_external>", line 940, in exec_module
  File "<frozen importlib._bootstrap>", line 241, in _call_with_frames_removed
  File "/Users/siddalingkattimani/airflow/dags/gpt_upload_csv_gcs.py", line 22, in <module>
    bucket_name = config.get("gcs", "bucket_name")
                  ^^^^^^^^^^^^^^^^^^^^^^^^^^^^^^^^
  File "/Library/Frameworks/Python.framework/Versions/3.11/lib/python3.11/configparser.py", line 797, in get
    d = self._unify_values(section, vars)
        ^^^^^^^^^^^^^^^^^^^^^^^^^^^^^^^^^
  File "/Library/Frameworks/Python.framework/Versions/3.11/lib/python3.11/configparser.py", line 1168, in _unify_values
    raise NoSectionError(section) from None
configparser.NoSectionError: No section: 'gcs'
[2023-04-24T22:12:19.935+0200] {processor.py:755} WARNING - No viable dags retrieved from /Users/siddalingkattimani/airflow/dags/gpt_upload_csv_gcs.py
[2023-04-24T22:12:20.491+0200] {processor.py:175} INFO - Processing /Users/siddalingkattimani/airflow/dags/gpt_upload_csv_gcs.py took 0.876 seconds
[2023-04-24T22:14:21.150+0200] {processor.py:153} INFO - Started process (PID=7101) to work on /Users/siddalingkattimani/airflow/dags/gpt_upload_csv_gcs.py
[2023-04-24T22:14:21.156+0200] {processor.py:743} INFO - Processing file /Users/siddalingkattimani/airflow/dags/gpt_upload_csv_gcs.py for tasks to queue
[2023-04-24T22:14:21.157+0200] {logging_mixin.py:137} INFO - [2023-04-24T22:14:21.157+0200] {dagbag.py:532} INFO - Filling up the DagBag from /Users/siddalingkattimani/airflow/dags/gpt_upload_csv_gcs.py
[2023-04-24T22:14:21.158+0200] {logging_mixin.py:137} INFO - [2023-04-24T22:14:21.158+0200] {dagbag.py:318} INFO - File /Users/siddalingkattimani/airflow/dags/gpt_upload_csv_gcs.py assumed to contain no DAGs. Skipping.
[2023-04-24T22:14:21.158+0200] {processor.py:755} WARNING - No viable dags retrieved from /Users/siddalingkattimani/airflow/dags/gpt_upload_csv_gcs.py
[2023-04-24T22:14:21.967+0200] {processor.py:175} INFO - Processing /Users/siddalingkattimani/airflow/dags/gpt_upload_csv_gcs.py took 0.819 seconds
[2023-04-24T22:16:19.568+0200] {processor.py:153} INFO - Started process (PID=7286) to work on /Users/siddalingkattimani/airflow/dags/gpt_upload_csv_gcs.py
[2023-04-24T22:16:19.572+0200] {processor.py:743} INFO - Processing file /Users/siddalingkattimani/airflow/dags/gpt_upload_csv_gcs.py for tasks to queue
[2023-04-24T22:16:19.572+0200] {logging_mixin.py:137} INFO - [2023-04-24T22:16:19.572+0200] {dagbag.py:532} INFO - Filling up the DagBag from /Users/siddalingkattimani/airflow/dags/gpt_upload_csv_gcs.py
[2023-04-24T22:16:19.572+0200] {logging_mixin.py:137} INFO - [2023-04-24T22:16:19.572+0200] {dagbag.py:318} INFO - File /Users/siddalingkattimani/airflow/dags/gpt_upload_csv_gcs.py assumed to contain no DAGs. Skipping.
[2023-04-24T22:16:19.573+0200] {processor.py:755} WARNING - No viable dags retrieved from /Users/siddalingkattimani/airflow/dags/gpt_upload_csv_gcs.py
[2023-04-24T22:16:20.287+0200] {processor.py:175} INFO - Processing /Users/siddalingkattimani/airflow/dags/gpt_upload_csv_gcs.py took 0.720 seconds
[2023-04-24T22:21:59.886+0200] {processor.py:153} INFO - Started process (PID=7732) to work on /Users/siddalingkattimani/airflow/dags/gpt_upload_csv_gcs.py
[2023-04-24T22:21:59.889+0200] {processor.py:743} INFO - Processing file /Users/siddalingkattimani/airflow/dags/gpt_upload_csv_gcs.py for tasks to queue
[2023-04-24T22:21:59.889+0200] {logging_mixin.py:137} INFO - [2023-04-24T22:21:59.889+0200] {dagbag.py:532} INFO - Filling up the DagBag from /Users/siddalingkattimani/airflow/dags/gpt_upload_csv_gcs.py
[2023-04-24T22:22:00.173+0200] {logging_mixin.py:137} INFO - [2023-04-24T22:22:00.172+0200] {dagbag.py:341} ERROR - Failed to import: /Users/siddalingkattimani/airflow/dags/gpt_upload_csv_gcs.py
Traceback (most recent call last):
  File "/Users/siddalingkattimani/dbt_env/lib/python3.11/site-packages/airflow/models/dagbag.py", line 337, in parse
    loader.exec_module(new_module)
  File "<frozen importlib._bootstrap_external>", line 940, in exec_module
  File "<frozen importlib._bootstrap>", line 241, in _call_with_frames_removed
  File "/Users/siddalingkattimani/airflow/dags/gpt_upload_csv_gcs.py", line 12, in <module>
    print(config['GoogleCloud']['bucket_name'])
          ~~~~~~^^^^^^^^^^^^^^^
  File "/Library/Frameworks/Python.framework/Versions/3.11/lib/python3.11/configparser.py", line 979, in __getitem__
    raise KeyError(key)
KeyError: 'GoogleCloud'
[2023-04-24T22:22:00.173+0200] {processor.py:755} WARNING - No viable dags retrieved from /Users/siddalingkattimani/airflow/dags/gpt_upload_csv_gcs.py
[2023-04-24T22:22:00.609+0200] {processor.py:175} INFO - Processing /Users/siddalingkattimani/airflow/dags/gpt_upload_csv_gcs.py took 0.724 seconds
[2023-04-24T22:24:05.592+0200] {processor.py:153} INFO - Started process (PID=7807) to work on /Users/siddalingkattimani/airflow/dags/gpt_upload_csv_gcs.py
[2023-04-24T22:24:05.602+0200] {processor.py:743} INFO - Processing file /Users/siddalingkattimani/airflow/dags/gpt_upload_csv_gcs.py for tasks to queue
[2023-04-24T22:24:05.603+0200] {logging_mixin.py:137} INFO - [2023-04-24T22:24:05.603+0200] {dagbag.py:532} INFO - Filling up the DagBag from /Users/siddalingkattimani/airflow/dags/gpt_upload_csv_gcs.py
[2023-04-24T22:24:06.253+0200] {logging_mixin.py:137} INFO - [2023-04-24T22:24:06.249+0200] {dagbag.py:341} ERROR - Failed to import: /Users/siddalingkattimani/airflow/dags/gpt_upload_csv_gcs.py
Traceback (most recent call last):
  File "/Users/siddalingkattimani/dbt_env/lib/python3.11/site-packages/airflow/models/dagbag.py", line 337, in parse
    loader.exec_module(new_module)
  File "<frozen importlib._bootstrap_external>", line 940, in exec_module
  File "<frozen importlib._bootstrap>", line 241, in _call_with_frames_removed
  File "/Users/siddalingkattimani/airflow/dags/gpt_upload_csv_gcs.py", line 12, in <module>
    print(config['GoogleCloud']['bucket_name'])
          ~~~~~~^^^^^^^^^^^^^^^
  File "/Library/Frameworks/Python.framework/Versions/3.11/lib/python3.11/configparser.py", line 979, in __getitem__
    raise KeyError(key)
KeyError: 'GoogleCloud'
[2023-04-24T22:24:06.254+0200] {processor.py:755} WARNING - No viable dags retrieved from /Users/siddalingkattimani/airflow/dags/gpt_upload_csv_gcs.py
[2023-04-24T22:24:07.234+0200] {processor.py:175} INFO - Processing /Users/siddalingkattimani/airflow/dags/gpt_upload_csv_gcs.py took 1.643 seconds
[2023-04-24T22:27:05.135+0200] {processor.py:153} INFO - Started process (PID=8007) to work on /Users/siddalingkattimani/airflow/dags/gpt_upload_csv_gcs.py
[2023-04-24T22:27:05.139+0200] {processor.py:743} INFO - Processing file /Users/siddalingkattimani/airflow/dags/gpt_upload_csv_gcs.py for tasks to queue
[2023-04-24T22:27:05.140+0200] {logging_mixin.py:137} INFO - [2023-04-24T22:27:05.140+0200] {dagbag.py:532} INFO - Filling up the DagBag from /Users/siddalingkattimani/airflow/dags/gpt_upload_csv_gcs.py
[2023-04-24T22:27:05.585+0200] {logging_mixin.py:137} INFO - [2023-04-24T22:27:05.583+0200] {dagbag.py:341} ERROR - Failed to import: /Users/siddalingkattimani/airflow/dags/gpt_upload_csv_gcs.py
Traceback (most recent call last):
  File "/Users/siddalingkattimani/dbt_env/lib/python3.11/site-packages/airflow/models/dagbag.py", line 337, in parse
    loader.exec_module(new_module)
  File "<frozen importlib._bootstrap_external>", line 940, in exec_module
  File "<frozen importlib._bootstrap>", line 241, in _call_with_frames_removed
  File "/Users/siddalingkattimani/airflow/dags/gpt_upload_csv_gcs.py", line 12, in <module>
    print(config['GoogleCloud']['bucket_name'])
          ~~~~~~^^^^^^^^^^^^^^^
  File "/Library/Frameworks/Python.framework/Versions/3.11/lib/python3.11/configparser.py", line 979, in __getitem__
    raise KeyError(key)
KeyError: 'GoogleCloud'
[2023-04-24T22:27:05.585+0200] {processor.py:755} WARNING - No viable dags retrieved from /Users/siddalingkattimani/airflow/dags/gpt_upload_csv_gcs.py
[2023-04-24T22:27:06.195+0200] {processor.py:175} INFO - Processing /Users/siddalingkattimani/airflow/dags/gpt_upload_csv_gcs.py took 1.062 seconds
[2023-04-24T22:29:42.967+0200] {processor.py:153} INFO - Started process (PID=8276) to work on /Users/siddalingkattimani/airflow/dags/gpt_upload_csv_gcs.py
[2023-04-24T22:29:42.971+0200] {processor.py:743} INFO - Processing file /Users/siddalingkattimani/airflow/dags/gpt_upload_csv_gcs.py for tasks to queue
[2023-04-24T22:29:42.971+0200] {logging_mixin.py:137} INFO - [2023-04-24T22:29:42.971+0200] {dagbag.py:532} INFO - Filling up the DagBag from /Users/siddalingkattimani/airflow/dags/gpt_upload_csv_gcs.py
[2023-04-24T22:29:43.368+0200] {logging_mixin.py:137} INFO - [2023-04-24T22:29:43.366+0200] {dagbag.py:341} ERROR - Failed to import: /Users/siddalingkattimani/airflow/dags/gpt_upload_csv_gcs.py
Traceback (most recent call last):
  File "/Users/siddalingkattimani/dbt_env/lib/python3.11/site-packages/airflow/models/dagbag.py", line 337, in parse
    loader.exec_module(new_module)
  File "<frozen importlib._bootstrap_external>", line 940, in exec_module
  File "<frozen importlib._bootstrap>", line 241, in _call_with_frames_removed
  File "/Users/siddalingkattimani/airflow/dags/gpt_upload_csv_gcs.py", line 12, in <module>
    print(config['GoogleCloud']['bucket_name'])
          ~~~~~~^^^^^^^^^^^^^^^
  File "/Library/Frameworks/Python.framework/Versions/3.11/lib/python3.11/configparser.py", line 979, in __getitem__
    raise KeyError(key)
KeyError: 'GoogleCloud'
[2023-04-24T22:29:43.369+0200] {processor.py:755} WARNING - No viable dags retrieved from /Users/siddalingkattimani/airflow/dags/gpt_upload_csv_gcs.py
[2023-04-24T22:29:43.986+0200] {processor.py:175} INFO - Processing /Users/siddalingkattimani/airflow/dags/gpt_upload_csv_gcs.py took 1.020 seconds
[2023-04-24T22:31:58.164+0200] {processor.py:153} INFO - Started process (PID=8498) to work on /Users/siddalingkattimani/airflow/dags/gpt_upload_csv_gcs.py
[2023-04-24T22:31:58.169+0200] {processor.py:743} INFO - Processing file /Users/siddalingkattimani/airflow/dags/gpt_upload_csv_gcs.py for tasks to queue
[2023-04-24T22:31:58.169+0200] {logging_mixin.py:137} INFO - [2023-04-24T22:31:58.169+0200] {dagbag.py:532} INFO - Filling up the DagBag from /Users/siddalingkattimani/airflow/dags/gpt_upload_csv_gcs.py
[2023-04-24T22:31:58.532+0200] {logging_mixin.py:137} INFO - [2023-04-24T22:31:58.527+0200] {dagbag.py:341} ERROR - Failed to import: /Users/siddalingkattimani/airflow/dags/gpt_upload_csv_gcs.py
Traceback (most recent call last):
  File "/Users/siddalingkattimani/dbt_env/lib/python3.11/site-packages/airflow/models/dagbag.py", line 337, in parse
    loader.exec_module(new_module)
  File "<frozen importlib._bootstrap_external>", line 940, in exec_module
  File "<frozen importlib._bootstrap>", line 241, in _call_with_frames_removed
  File "/Users/siddalingkattimani/airflow/dags/gpt_upload_csv_gcs.py", line 12, in <module>
    print(config['GoogleCloud']['bucket_name'])
          ~~~~~~^^^^^^^^^^^^^^^
  File "/Library/Frameworks/Python.framework/Versions/3.11/lib/python3.11/configparser.py", line 979, in __getitem__
    raise KeyError(key)
KeyError: 'GoogleCloud'
[2023-04-24T22:31:58.533+0200] {processor.py:755} WARNING - No viable dags retrieved from /Users/siddalingkattimani/airflow/dags/gpt_upload_csv_gcs.py
[2023-04-24T22:31:59.243+0200] {processor.py:175} INFO - Processing /Users/siddalingkattimani/airflow/dags/gpt_upload_csv_gcs.py took 1.079 seconds
[2023-04-24T22:34:16.273+0200] {processor.py:153} INFO - Started process (PID=8706) to work on /Users/siddalingkattimani/airflow/dags/gpt_upload_csv_gcs.py
[2023-04-24T22:34:16.277+0200] {processor.py:743} INFO - Processing file /Users/siddalingkattimani/airflow/dags/gpt_upload_csv_gcs.py for tasks to queue
[2023-04-24T22:34:16.278+0200] {logging_mixin.py:137} INFO - [2023-04-24T22:34:16.278+0200] {dagbag.py:532} INFO - Filling up the DagBag from /Users/siddalingkattimani/airflow/dags/gpt_upload_csv_gcs.py
[2023-04-24T22:34:16.639+0200] {logging_mixin.py:137} INFO - [2023-04-24T22:34:16.634+0200] {dagbag.py:341} ERROR - Failed to import: /Users/siddalingkattimani/airflow/dags/gpt_upload_csv_gcs.py
Traceback (most recent call last):
  File "/Users/siddalingkattimani/dbt_env/lib/python3.11/site-packages/airflow/models/dagbag.py", line 337, in parse
    loader.exec_module(new_module)
  File "<frozen importlib._bootstrap_external>", line 940, in exec_module
  File "<frozen importlib._bootstrap>", line 241, in _call_with_frames_removed
  File "/Users/siddalingkattimani/airflow/dags/gpt_upload_csv_gcs.py", line 12, in <module>
    print(config['GoogleCloud']['bucket_name'])
          ~~~~~~^^^^^^^^^^^^^^^
  File "/Library/Frameworks/Python.framework/Versions/3.11/lib/python3.11/configparser.py", line 979, in __getitem__
    raise KeyError(key)
KeyError: 'GoogleCloud'
[2023-04-24T22:34:16.640+0200] {processor.py:755} WARNING - No viable dags retrieved from /Users/siddalingkattimani/airflow/dags/gpt_upload_csv_gcs.py
[2023-04-24T22:34:17.157+0200] {processor.py:175} INFO - Processing /Users/siddalingkattimani/airflow/dags/gpt_upload_csv_gcs.py took 0.885 seconds
[2023-04-24T22:36:35.555+0200] {processor.py:153} INFO - Started process (PID=8968) to work on /Users/siddalingkattimani/airflow/dags/gpt_upload_csv_gcs.py
[2023-04-24T22:36:35.559+0200] {processor.py:743} INFO - Processing file /Users/siddalingkattimani/airflow/dags/gpt_upload_csv_gcs.py for tasks to queue
[2023-04-24T22:36:35.559+0200] {logging_mixin.py:137} INFO - [2023-04-24T22:36:35.559+0200] {dagbag.py:532} INFO - Filling up the DagBag from /Users/siddalingkattimani/airflow/dags/gpt_upload_csv_gcs.py
[2023-04-24T22:36:35.953+0200] {logging_mixin.py:137} INFO - [2023-04-24T22:36:35.949+0200] {dagbag.py:341} ERROR - Failed to import: /Users/siddalingkattimani/airflow/dags/gpt_upload_csv_gcs.py
Traceback (most recent call last):
  File "/Users/siddalingkattimani/dbt_env/lib/python3.11/site-packages/airflow/models/dagbag.py", line 337, in parse
    loader.exec_module(new_module)
  File "<frozen importlib._bootstrap_external>", line 940, in exec_module
  File "<frozen importlib._bootstrap>", line 241, in _call_with_frames_removed
  File "/Users/siddalingkattimani/airflow/dags/gpt_upload_csv_gcs.py", line 12, in <module>
    print(config['GoogleCloud']['bucket_name'])
          ~~~~~~^^^^^^^^^^^^^^^
  File "/Library/Frameworks/Python.framework/Versions/3.11/lib/python3.11/configparser.py", line 979, in __getitem__
    raise KeyError(key)
KeyError: 'GoogleCloud'
[2023-04-24T22:36:35.954+0200] {processor.py:755} WARNING - No viable dags retrieved from /Users/siddalingkattimani/airflow/dags/gpt_upload_csv_gcs.py
[2023-04-24T22:36:36.739+0200] {processor.py:175} INFO - Processing /Users/siddalingkattimani/airflow/dags/gpt_upload_csv_gcs.py took 1.185 seconds
[2023-04-24T22:39:16.506+0200] {processor.py:153} INFO - Started process (PID=9309) to work on /Users/siddalingkattimani/airflow/dags/gpt_upload_csv_gcs.py
[2023-04-24T22:39:16.511+0200] {processor.py:743} INFO - Processing file /Users/siddalingkattimani/airflow/dags/gpt_upload_csv_gcs.py for tasks to queue
[2023-04-24T22:39:16.512+0200] {logging_mixin.py:137} INFO - [2023-04-24T22:39:16.512+0200] {dagbag.py:532} INFO - Filling up the DagBag from /Users/siddalingkattimani/airflow/dags/gpt_upload_csv_gcs.py
[2023-04-24T22:39:16.859+0200] {logging_mixin.py:137} INFO - [2023-04-24T22:39:16.853+0200] {dagbag.py:341} ERROR - Failed to import: /Users/siddalingkattimani/airflow/dags/gpt_upload_csv_gcs.py
Traceback (most recent call last):
  File "/Users/siddalingkattimani/dbt_env/lib/python3.11/site-packages/airflow/models/dagbag.py", line 337, in parse
    loader.exec_module(new_module)
  File "<frozen importlib._bootstrap_external>", line 940, in exec_module
  File "<frozen importlib._bootstrap>", line 241, in _call_with_frames_removed
  File "/Users/siddalingkattimani/airflow/dags/gpt_upload_csv_gcs.py", line 12, in <module>
    print(config['GoogleCloud']['bucket_name'])
          ~~~~~~^^^^^^^^^^^^^^^
  File "/Library/Frameworks/Python.framework/Versions/3.11/lib/python3.11/configparser.py", line 979, in __getitem__
    raise KeyError(key)
KeyError: 'GoogleCloud'
[2023-04-24T22:39:16.860+0200] {processor.py:755} WARNING - No viable dags retrieved from /Users/siddalingkattimani/airflow/dags/gpt_upload_csv_gcs.py
[2023-04-24T22:39:17.412+0200] {processor.py:175} INFO - Processing /Users/siddalingkattimani/airflow/dags/gpt_upload_csv_gcs.py took 0.906 seconds
[2023-04-24T22:41:47.704+0200] {processor.py:153} INFO - Started process (PID=9596) to work on /Users/siddalingkattimani/airflow/dags/gpt_upload_csv_gcs.py
[2023-04-24T22:41:47.710+0200] {processor.py:743} INFO - Processing file /Users/siddalingkattimani/airflow/dags/gpt_upload_csv_gcs.py for tasks to queue
[2023-04-24T22:41:47.711+0200] {logging_mixin.py:137} INFO - [2023-04-24T22:41:47.711+0200] {dagbag.py:532} INFO - Filling up the DagBag from /Users/siddalingkattimani/airflow/dags/gpt_upload_csv_gcs.py
[2023-04-24T22:41:48.304+0200] {logging_mixin.py:137} INFO - [2023-04-24T22:41:48.297+0200] {dagbag.py:341} ERROR - Failed to import: /Users/siddalingkattimani/airflow/dags/gpt_upload_csv_gcs.py
Traceback (most recent call last):
  File "/Users/siddalingkattimani/dbt_env/lib/python3.11/site-packages/airflow/models/dagbag.py", line 337, in parse
    loader.exec_module(new_module)
  File "<frozen importlib._bootstrap_external>", line 940, in exec_module
  File "<frozen importlib._bootstrap>", line 241, in _call_with_frames_removed
  File "/Users/siddalingkattimani/airflow/dags/gpt_upload_csv_gcs.py", line 12, in <module>
    print(config['GoogleCloud']['bucket_name'])
          ~~~~~~^^^^^^^^^^^^^^^
  File "/Library/Frameworks/Python.framework/Versions/3.11/lib/python3.11/configparser.py", line 979, in __getitem__
    raise KeyError(key)
KeyError: 'GoogleCloud'
[2023-04-24T22:41:48.305+0200] {processor.py:755} WARNING - No viable dags retrieved from /Users/siddalingkattimani/airflow/dags/gpt_upload_csv_gcs.py
[2023-04-24T22:41:50.064+0200] {processor.py:175} INFO - Processing /Users/siddalingkattimani/airflow/dags/gpt_upload_csv_gcs.py took 2.361 seconds
